Workbook
Name _____top1: {30,140,350,160,"",""}
Name _____top1: {30,140,350,160,"",""}
Name _____top1: {30,140,350,160,"",""}
Name _____top1: {30,140,350,160,"",""}
Name ____C65537: #REF!
Name ____C65537: #REF!
Name ____C65537: #REF!
Name ____top1: {30,140,350,160,"",""}
Name ____top1: {30,140,350,160,"",""}
Name ____top1: {30,140,350,160,"",""}
Name ____top1: {30,140,350,160,"",""}
Name ___C65537: #REF!
Name ___C65537: #REF!
Name ___C65537: #REF!
Name ___top1: {30,140,350,160,"",""}
Name ___top1: {30,140,350,160,"",""}
Name ___top1: {30,140,350,160,"",""}
Name ___top1: {30,140,350,160,"",""}
Name __C65537: #REF!
Name __C65537: #REF!
Name __C65537: #REF!
Name __I______AU__E: #REF!
Name __I______AU__E: #REF!
Name __I______AU__E: #REF!
Name __top1: {30,140,350,160,"",""}
Name __top1: {30,140,350,160,"",""}
Name __top1: {30,140,350,160,"",""}
Name __top1: {30,140,350,160,"",""}
Name _08: #REF!
Name _08: #REF!
Name _08: #REF!
Name _C65537: #REF!
Name _C65537: #REF!
Name _C65537: #REF!
Name _top1: {30,140,350,160,"",""}
Name _top1: {30,140,350,160,"",""}
Name _top1: {30,140,350,160,"",""}
Name _top1: {30,140,350,160,"",""}
Name a: {30,140,350,160,"",""}
Name a: {30,140,350,160,"",""}
Name a: {30,140,350,160,"",""}
Name a: {30,140,350,160,"",""}
Name ad: {30,140,350,160,"",""}
Name ad: {30,140,350,160,"",""}
Name ad: {30,140,350,160,"",""}
Name ad: {30,140,350,160,"",""}
Name AE1148677: '[1]Жиззах янги раз'!#REF!
Name AE1148677: '[1]Жиззах янги раз'!#REF!
Name af: {30,140,350,160,"",""}
Name af: {30,140,350,160,"",""}
Name af: {30,140,350,160,"",""}
Name af: {30,140,350,160,"",""}
Name ag: #REF!
Name ag: #REF!
Name ag: #REF!
Name ah: {30,140,350,160,"",""}
Name ah: {30,140,350,160,"",""}
Name ah: {30,140,350,160,"",""}
Name ah: {30,140,350,160,"",""}
Name aj: {30,140,350,160,"",""}

Sheet свод
B1: Турар-жой ва нотурар-жой кўчмас мулк объектлари Жисмоний ва Юридик шахслар томонидан Узкад дастурига келган аризаларни муддати бузилиш бўйича МАЪЛУМОТ
C2: 26.06.2026-йил соат 16:20 холатига
B3: № | C3: Худудлар | D3: Жами якунлаш керак | E3: Шундан Муддати ўтган аризалар | G3: Бугун муддати тугайдиган | H3: Объект тури | J3: Шундан жараёнда турган рўллар кесмида | DD3: Муддат бузилишни олдини-олиш мақсадида тахлил
E4: Филиал томонида ўтган | F4: Регистрация томонидан ўтган | H4: Турар | I4: Нотурар | J4: Рахбар, Бош мухандис | K4: Arizani qabul qilish | L4: Arizani rad etish | M4: Arizani tasdiqlash | N4: Arizani yo'naltirish | O4: Rad qilish sababini o'rganish | P4: Ko'chmas mulkni UZKAD ga migratsiya qilish | Q4: Migratisya qilingan obyekt holatini tekshirish | R4: Ko‘chmas mulkni tanlash | S4: Arizani ko'rib chiqish | T4: Kadastr muhandisini tanlash | U4: Ko'chmas mulk turini tanlash | V4: Rad qilish | W4: ijrochi tanlash | X4: Ko'chmas mulk turini tanlash | Y4: Кадастр мухандис | Z4: Ijroga qabul qilish | AA4: Joyida o'rganish va ma'lumotlarni kiritish | AB4: Asosiy qismdan ajratish jarayonida | AC4: Umumiy foydalanishdagi obyekt yaratilish | AD4: Migratsiya qilinadigan kadastr raqamini kiritish | AE4: O'zida qolgan obyektni yaratish | AF4: O'lchov natijalarini kiritish | AG4: Топограф | AH4: ДКЯТ | AI4: Yer uchastkasini yaratish | AJ4: ДКЯТ Бошқарма | AK4: Kelishish (Boshqarma) | AL4: ДКП Келишиш | AM4: Kelishish (DKP) | AN4: Kelishish | AO4: Kelishish (Registratsiya DKP) | AP4: ДКЯТ | AQ4: Manzil biriktirish | AR4: Bino va inshootlarni yaratish | AS4: Dov daraxtlarni yaratish | AT4: Yer uchastkasini tahrirlash | AU4: Ер баланс | AV4: Yer toifasi va maqsadini kiritish | AW4: Auksion yer tekshirish | AX4: Yer turlarini kiritish | AY4: Ma'lumotlarni kiritish | AZ4: Yer tekshirish | BA4: Кадастр мухандис | BB4: Bino va inshoot ma'lumotlarini to‘ldirish | BC4: Inventarizatsiya ma'lumotlarini to‘ldirish | BD4: Yer uchastkasiga huquqiy hujjatlarni kiritsh | BE4: Bino-inshootlarga huquqiy hujjatlarni kiritsh | BF4: Kadastr qiymatini hisoblash va kiritish | BG4: Kadastr raqam biriktirish | BH4: Kadastr yig'ma jildni tayyorlash | BI4: Huquqni yaratish | BJ4: Hujjatlarni o'rganish | BK4: Ma'lumotlarni tekshirish | BL4: Рахбар, Бош мухандис | BM4: Tekshirish | BN4: Hujjatlarni tekshirish | BO4: Tasdiqlash | BP4: tekshirish/tasdiqlash | BQ4: Ma'lumotlarni tasdiqlash | BR4: Регистрация текшириш | BS4: Ro'yxatdan o'tkazish ma'lumotlarini tekshirish | BT4: Kamchiliklar bo'yicha habarnoma yuborish va 3 kunga to'xtatish | BU4: Hisobga olish | BV4: Yer uchastkasiga huquq yaratish | BW4: Bino-inshootga huquq yaratish | BX4: Cheklov yaratish | BY4: Taqiq yaratish | BZ4: Бино Бошқарма | CA4: Soliq maydonini tekshirish | CB4: Кадастр мухандис | CC4: Kadastr yig'majildini shakllantirish | CD4: Рахбар, Бош мухандис | CE4: Kadastr passportini shakllantirish | CF4: Yig'ma jildni tasdiqlash | CG4: To'lov yoki bepul tasdiqlash | CH4: Bog'liq arizani kutish | CI4: To'lovga chiqarish | CJ4: Hisobga qo'yish | CK4: Тўлов кутилмоқда | CL4: Регистрация ўтказиш | CM4: Arizani qabul qilish2 | CN4: Huquqlarni tekshirish | CO4: Ko'chmas mulkni ro'yhatdan o'tkazishga qabul qilish | CP4: Ro'yxatdan o'tkazish | CQ4: Kadastr pasporti va ko'chirmani yuborish | CR4: Rad qilish2 | CS4: Ko'chirmani yuborish | CT4: Ma‘lumotlarni tekshirish | CU4: Кадастр мухандис | CV4: Kadastr yig'majildini chop etish va arxiv ishiga tikish | CW4: Архивариус | CX4: Kadastr yig‘majildini qabul qilish, arizani yakunlash | CY4: Next Cloudga yuklash | CZ4: Келишиш кутилмоқда | DA4: ЯКУНЛАНДИ | DB4: Рад этилганлар | DC4: ҚОЛДИ | DD4: Муддати бузилишга 1-кун қолган | DE4: Муддати бузилишга 2-кун қолган | DF4: Муддати бузилишга 3-кун қолган | DG4: Муддати бузилишга 4-кун қолган | DH4: Муддати бузилишга 5-кун қолган | DI4: Муддати бузилишга 6-10-кун қолган | DJ4: Муддати бузилишга 10 кундан кўп
C5: НАМАНГАН | D5: =+D6+D21+D35+D49+D100+D117+D141+D161+D180+D194+D208+D227 -> 276 | E5: =+E6+E21+E35+E49+E100+E117+E141+E161+E180+E194+E208+E227 -> 67 | F5: =+F6+F21+F35+F49+F100+F117+F141+F161+F180+F194+F208+F227 -> 17 | G5: =+G6+G21+G35+G49+G100+G117+G141+G161+G180+G194+G208+G227 -> 192 | H5: =+H6+H21+H35+H49+H100+H117+H141+H161+H180+H194+H208+H227 -> 226 | I5: =+I6+I21+I35+I49+I100+I117+I141+I161+I180+I194+I208+I227 -> 50 | J5: =+J6+J21+J35+J49+J100+J117+J141+J161+J180+J194+J208+J227 -> 9 | K5: =+K6+K21+K35+K49+K100+K117+K141+K161+K180+K194+K208+K227 -> 1 | ... DC5: =+DC6+DC21+DC35+DC49+DC100+DC117+DC141+DC161+DC180+DC194+DC208+DC227 -> -174 | DD5: =+DD6+DD21+DD35+DD49+DD100+DD117+DD141+DD161+DD180+DD194+DD208+DD227+DD99 -> 0 | DE5: =+DE6+DE21+DE35+DE49+DE100+DE117+DE141+DE161+DE180+DE194+DE208+DE227+DE99 -> 0 | DF5: =+DF6+DF21+DF35+DF49+DF100+DF117+DF141+DF161+DF180+DF194+DF208+DF227+DF99 -> 237 | DG5: =+DG6+DG21+DG35+DG49+DG100+DG117+DG141+DG161+DG180+DG194+DG208+DG227+DG99 -> 232 | DH5: =+DH6+DH21+DH35+DH49+DH100+DH117+DH141+DH161+DH180+DH194+DH208+DH227+DH99 -> 289 | DI5: =+DI6+DI21+DI35+DI49+DI100+DI117+DI141+DI161+DI180+DI194+DI208+DI227+DI99 -> 1029 | DJ5: =+DJ6+DJ21+DJ35+DJ49+DJ100+DJ117+DJ141+DJ161+DJ180+DJ194+DJ208+DJ227+DJ99 -> 1061
A6: KSST | B6: 1 | C6: Косонсой тумани | D6: =+COUNTIFS('muddati otgan'!B:B,A6,'muddati otgan'!B:B,A6) -> 19 | E6: =SUMIFS('muddati otgan'!$V:V,'muddati otgan'!$B:B,$A:A) -> 1 | F6: =SUMIFS('muddati otgan'!$W:W,'muddati otgan'!$B:B,$A:A) -> 0 | G6: =SUMIFS('muddati otgan'!$U:U,'muddati otgan'!$B:B,$A:A) -> 18 | H6: =SUMIFS('muddati otgan'!$G:G,'muddati otgan'!$B:B,$A:A) -> 12 | I6: =SUMIFS('muddati otgan'!$H:H,'muddati otgan'!$B:B,$A:A) -> 7 | J6: =K6+P6+Q6+R6+S6+T6+U6+V6+W6+L6+O6+M6+N6+X6 -> 0 | K6: =+COUNTIFS('muddati otgan'!B:B,A6,'muddati otgan'!AA:AA,"Arizani qabul qilish") -> 0 | L6: =+COUNTIFS('muddati otgan'!B:B,A6,'muddati otgan'!J:J,"Arizani rad etish") -> 0 | M6: =+COUNTIFS('muddati otgan'!B:B,A6,'muddati otgan'!J:J,"Arizani tasdiqlash") -> 0 | N6: =+COUNTIFS('muddati otgan'!B:B,A6,'muddati otgan'!J:J,"Arizani yo'naltirish") -> 0 | O6: =+COUNTIFS('muddati otgan'!B:B,A6,'muddati otgan'!J:J,"Rad qilish sababini o'rganish") -> 0 | P6: =+COUNTIFS('muddati otgan'!B:B,A6,'muddati otgan'!J:J,"Ko'chmas mulkni UZKAD ga migratsiya qilish") -> 0 | Q6: =+COUNTIFS('muddati otgan'!B:B,A6,'muddati otgan'!J:J,"Migratisya qilingan obyekt holatini tekshirish") -> 0 | R6: =+COUNTIFS('muddati otgan'!B:B,A6,'muddati otgan'!J:J,"Ko‘chmas mulkni tanlash") -> 0 | S6: =+COUNTIFS('muddati otgan'!B:B,A6,'muddati otgan'!J:J,"Arizani ko'rib chiqish") -> 0 | T6: =+COUNTIFS('muddati otgan'!B:B,A6,'muddati otgan'!J:J,"Kadastr muhandisini tanlash") -> 0 | U6: =+COUNTIFS('muddati otgan'!B:B,A6,'muddati otgan'!J:J,"Ko'chmas mulk turini tanlahsh") -> 0 | V6: =+COUNTIFS('muddati otgan'!B:B,A6,'muddati otgan'!AA:AA,"Rad qilish") -> 0 | W6: =+COUNTIFS('muddati otgan'!B:B,A6,'muddati otgan'!J:J,"ijrochi tanlash") -> 0 | X6: =+COUNTIFS('muddati otgan'!B:B,A6,'muddati otgan'!J:J,"Ko'chmas mulk turini tanlash") -> 0 | Y6: =Z6+AD6+AF6+AE6+AC6+AB6+AA6 -> 0 | Z6: =+COUNTIFS('muddati otgan'!B:B,A6,'muddati otgan'!J:J,"Ijroga qabul qilish") -> 0 | AA6: =+COUNTIFS('muddati otgan'!B:B,A6,'muddati otgan'!J:J,"Joyida o'rganish va ma'lumotlarni kiritish") -> 0 | AB6: =+COUNTIFS('muddati otgan'!B:B,A6,'muddati otgan'!J:J,"Asosiy qismdan ajratish jarayonida") -> 0 | AC6: =+COUNTIFS('muddati otgan'!B:B,A6,'muddati otgan'!J:J,"Umumiy foydalanishdagi obyekt yaratilish") -> 0 | AD6: =+COUNTIFS('muddati otgan'!B:B,A6,'muddati otgan'!J:J,"Migratsiya qilinadigan kadastr raqamini kiritish") -> 0 | AE6: =+COUNTIFS('muddati otgan'!B:B,A6,'muddati otgan'!J:J,"O'zida qolgan obyektni yaratish") -> 0 | AF6: =+COUNTIFS('muddati otgan'!B:B,A6,'muddati otgan'!J:J,"O'lchov natijalarini kiritish") -> 0 | AG6: =+COUNTIFS('muddati otgan'!B:B,A6,'muddati otgan'!J:J,"Topoxaritani tayyorlash (dwg, pdf)") -> 0 | AH6: =AI6 -> 0 | AI6: =+COUNTIFS('muddati otgan'!B:B,A6,'muddati otgan'!J:J,"Yer uchastkasini yaratish") -> 0 | AJ6: =AK6 -> 0 | AK6: =+COUNTIFS('muddati otgan'!B:B,A6,'muddati otgan'!J:J,"Kelishish (Boshqarma)") -> 0 | AL6: =AM6+AN6+AO6 -> 0 | AM6: =+COUNTIFS('muddati otgan'!B:B,A6,'muddati otgan'!J:J,"Kelishish (DKP)") -> 0 | AN6: =+COUNTIFS('muddati otgan'!B:B,A6,'muddati otgan'!J:J,"Kelishish") -> 0 | AO6: =+COUNTIFS('muddati otgan'!B:B,A6,'muddati otgan'!J:J,"Kelishish (Registratsiya DKP)") -> 0 | AP6: =AQ6+AR6+AS6+AT6 -> 0 | AQ6: =+COUNTIFS('muddati otgan'!B:B,A6,'muddati otgan'!J:J,"Manzil biriktirish") -> 0 | AR6: =+COUNTIFS('muddati otgan'!B:B,A6,'muddati otgan'!J:J,"Bino va inshootlarni yaratish") -> 0 | AS6: =+COUNTIFS('muddati otgan'!B:B,A6,'muddati otgan'!J:J,"Dov daraxtlarni yaratish") -> 0 | AT6: =+COUNTIFS('muddati otgan'!B:B,A6,'muddati otgan'!J:J,"Yer uchastkasini tahrirlash") -> 0 | AU6: =AV6+AW6+AX6+AY6+AZ6 -> 0 | AV6: =+COUNTIFS('muddati otgan'!B:B,A6,'muddati otgan'!J:J,"Yer toifasi va maqsadini kiritish") -> 0 | AW6: =+COUNTIFS('muddati otgan'!B:B,A6,'muddati otgan'!J:J,"Auksion yer tekshirish") -> 0 | AX6: =+COUNTIFS('muddati otgan'!B:B,A6,'muddati otgan'!J:J,"Yer turlarini kiritish") -> 0 | AY6: =+COUNTIFS('muddati otgan'!B:B,A6,'muddati otgan'!J:J,"Ma'lumotlarni kiritish") -> 0 | AZ6: =+COUNTIFS('muddati otgan'!B:B,A6,'muddati otgan'!J:J,"Yer tekshirish") -> 0 | BA6: =BB6+BC6+BD6+BE6+BF6+BG6+BH6+BI6+BJ6+BK6 -> 0 | BB6: =+COUNTIFS('muddati otgan'!B:B,A6,'muddati otgan'!J:J,"Bino va inshoot ma'lumotlarini to‘ldirish") -> 0 | BC6: =+COUNTIFS('muddati otgan'!B:B,A6,'muddati otgan'!J:J,"Inventarizatsiya ma'lumotlarini to‘ldirish") -> 0 | BD6: =+COUNTIFS('muddati otgan'!B:B,A6,'muddati otgan'!J:J,"Yer uchastkasiga huquqiy hujjatlarni kiritsh") -> 0 | BE6: =+COUNTIFS('muddati otgan'!B:B,A6,'muddati otgan'!J:J,"Bino-inshootlarga huquqiy hujjatlarni kiritsh") -> 0 | BF6: =+COUNTIFS('muddati otgan'!B:B,A6,'muddati otgan'!J:J,"Kadastr qiymatini hisoblash va kiritish") -> 0 | BG6: =+COUNTIFS('muddati otgan'!B:B,A6,'muddati otgan'!J:J,"Kadastr raqam biriktirish") -> 0 | BH6: =+COUNTIFS('muddati otgan'!B:B,A6,'muddati otgan'!J:J,"Kadastr yig'ma jildni tayyorlash") -> 0 | BI6: =+COUNTIFS('muddati otgan'!B:B,A6,'muddati otgan'!J:J,"Huquqni yaratish") -> 0 | BJ6: =+COUNTIFS('muddati otgan'!B:B,A6,'muddati otgan'!J:J,"Hujjatlarni o'rganish") -> 0 | BK6: =+COUNTIFS('muddati otgan'!B:B,A6,'muddati otgan'!J:J,"Ma'lumotlarni tekshirish") -> 0 | BL6: =BM6+BN6+BP6+BO6+BQ6 -> 0 | BM6: =+COUNTIFS('muddati otgan'!B:B,A6,'muddati otgan'!J:J,"Tekshirish") -> 0 | BN6: =+COUNTIFS('muddati otgan'!B:B,A6,'muddati otgan'!J:J,"Hujjatlarni tekshirish") -> 0 | BO6: =+COUNTIFS('muddati otgan'!B:B,A6,'muddati otgan'!J:J,"Tasdiqlash") -> 0 | BP6: =+COUNTIFS('muddati otgan'!B:B,A6,'muddati otgan'!J:J,"tekshirish/tasdiqlash") -> 0 | BQ6: =+COUNTIFS('muddati otgan'!B:B,A6,'muddati otgan'!J:J,"Ma'lumotlarni tasdiqlash") -> 0 | BR6: =BS6+BU6+BV6+BW6+BX6+BY6-BT6 -> 4 | BS6: =+COUNTIFS('muddati otgan'!B:B,A6,'muddati otgan'!J:J,"Ro'yxatdan o'tkazish ma'lumotlarini tekshirish") -> 4 | BT6: =+COUNTIFS('muddati otgan'!B:B,A6,'muddati otgan'!J:J,"Kamchiliklar bo'yicha habarnoma yuborish va 3 kunga to'xtatish") -> 0 | BU6: =+COUNTIFS('muddati otgan'!B:B,A6,'muddati otgan'!J:J,"Hisobga olish") -> 0 | BV6: =+COUNTIFS('muddati otgan'!B:B,A6,'muddati otgan'!J:J,"Yer uchastkasiga huquq yaratish") -> 0 | BW6: =+COUNTIFS('muddati otgan'!B:B,A6,'muddati otgan'!J:J,"Bino-inshootga huquq yaratish") -> 0 | BX6: =+COUNTIFS('muddati otgan'!B:B,A6,'muddati otgan'!J:J,"Cheklov yaratish") -> 0 | BY6: =+COUNTIFS('muddati otgan'!B:B,A6,'muddati otgan'!J:J,"Taqiq yaratish") -> 0 | BZ6: =CA6 -> 0 | CA6: =+COUNTIFS('muddati otgan'!B:B,A6,'muddati otgan'!J:J,"Soliq maydonini tekshirish") -> 0 | CB6: =CC6 -> 0 | CC6: =+COUNTIFS('muddati otgan'!B:B,A6,'muddati otgan'!J:J,"Kadastr yig'majildini shakllantirish") -> 0 | CD6: =CE6+CF6+CG6+CI6+CJ6+CH6 -> 0 | CE6: =+COUNTIFS('muddati otgan'!B:B,A6,'muddati otgan'!J:J,"Kadastr passportini shakllantirish") -> 0 | CF6: =+COUNTIFS('muddati otgan'!B:B,A6,'muddati otgan'!J:J,"Yig'ma jildni tasdiqlash") -> 0 | CG6: =+COUNTIFS('muddati otgan'!B:B,A6,'muddati otgan'!J:J,"To'lov yoki bepul tasdiqlash") -> 0 | CH6: =+COUNTIFS('muddati otgan'!B:B,A6,'muddati otgan'!J:J,"Bog'liq arizani kutish") -> 0 | CI6: =+COUNTIFS('muddati otgan'!B:B,A6,'muddati otgan'!J:J,"To'lovga chiqarish") -> 0 | CJ6: =+COUNTIFS('muddati otgan'!B:B,A6,'muddati otgan'!J:J,"Hisobga qo'yish") -> 0 | CK6: =+COUNTIFS('muddati otgan'!B:B,A6,'muddati otgan'!J:J,"To'lov kutilmoqda") -> 8 | CL6: =CM6+CN6+CO6+CP6+CQ6+CR6+CS6+CT6 -> 0 | CM6: =+COUNTIFS('muddati otgan'!B:B,A6,'muddati otgan'!AA:AA,"Arizani qabul qilish2") -> 0 | CN6: =+COUNTIFS('muddati otgan'!B:B,A6,'muddati otgan'!J:J,"Huquqlarni tekshirish") -> 0 | CO6: =+COUNTIFS('muddati otgan'!B:B,A6,'muddati otgan'!J:J,"Ko'chmas mulkni ro'yhatdan o'tkazishga qabul qilish") -> 0 | CP6: =+COUNTIFS('muddati otgan'!B:B,A6,'muddati otgan'!J:J,"Ro'yxatdan o'tkazish") -> 0 | CQ6: =+COUNTIFS('muddati otgan'!B:B,A6,'muddati otgan'!J:J,"Kadastr pasporti va ko'chirmani yuborish") -> 0 | CR6: =+COUNTIFS('muddati otgan'!B:B,A6,'muddati otgan'!AA:AA,"Rad qilish2") -> 0 | CS6: =+COUNTIFS('muddati otgan'!B:B,A6,'muddati otgan'!J:J,"Ko'chirmani yuborish") -> 0 | CT6: =+COUNTIFS('muddati otgan'!B:B,A6,'muddati otgan'!J:J,"Ma‘lumotlarni tekshirish") -> 0 | CU6: =CV6 -> 0 | CV6: =+COUNTIFS('muddati otgan'!B:B,A6,'muddati otgan'!J:J,"Kadastr yig'majildini chop etish va arxiv ishiga tikish") -> 0 | CW6: =CX6+CY6 -> 0 | CX6: =+COUNTIFS('muddati otgan'!B:B,A6,'muddati otgan'!J:J,"Kadastr yig‘majildini qabul qilish, arizani yakunlash") -> 0 | CY6: =+COUNTIFS('muddati otgan'!B:B,A6,'muddati otgan'!J:J,"Next Cloudga yuklash") -> 0 | CZ6: =+COUNTIFS('muddati otgan'!B:B,A6,'muddati otgan'!J:J,"Kelishish kutilmoqda") -> 0 | DA6: =+COUNTIFS('muddati otgan'!B:B,A6,'muddati otgan'!J:J,"Yakunlandi") -> 7 | DB6: =+COUNTIFS('muddati otgan'!B:B,A6,'muddati otgan'!J:J,"Rad etildi") -> 0 | DC6: =CK6+CZ6+DA6+DB6-D6 -> -4 | DD6: =COUNTIFS('jami 1-20 kunlik arizalar'!B:B,A:A,'jami 1-20 kunlik arizalar'!S:S,"1") -> 0 | DE6: =COUNTIFS('jami 1-20 kunlik arizalar'!B:B,A:A,'jami 1-20 kunlik arizalar'!S:S,"2") -> 0 | DF6: =COUNTIFS('jami 1-20 kunlik arizalar'!B:B,A:A,'jami 1-20 kunlik arizalar'!S:S,"3") -> 25 | DG6: =COUNTIFS('jami 1-20 kunlik arizalar'!B:B,A:A,'jami 1-20 kunlik arizalar'!S:S,"4") -> 9 | DH6: =COUNTIFS('jami 1-20 kunlik arizalar'!B:B,A:A,'jami 1-20 kunlik arizalar'!S:S,"5") -> 14 | DI6: =SUM(COUNTIFS('jami 1-20 kunlik arizalar'!B:B,A:A, 'jami 1-20 kunlik arizalar'!S:S, {6,7,8,9,10})) -> 87 | DJ6: =SUMPRODUCT(('jami 1-20 kunlik arizalar'!B:B=A6)*('jami 1-20 kunlik arizalar'!S:S>10)) -> 79
A7: 50709025980034 | C7: ABDUHAMIDXONOV MURODXON | D7: =+COUNTIFS('muddati otgan'!C:C,A7,'muddati otgan'!C:C,A7) -> 3 | E7: =SUMIFS('muddati otgan'!$V:V,'muddati otgan'!$C:C,$A:A) -> 0 | F7: =SUMIFS('muddati otgan'!$W:W,'muddati otgan'!$C:C,$A:A) -> 0 | G7: =SUMIFS('muddati otgan'!$U:U,'muddati otgan'!$C:C,$A:A) -> 3 | H7: =SUMIFS('muddati otgan'!$G:G,'muddati otgan'!$C:C,$A:A) -> 3 | I7: =SUMIFS('muddati otgan'!$H:H,'muddati otgan'!$C:C,$A:A) -> 0 | J7: =K7+P7+Q7+R7+S7+T7+U7+V7+W7+L7+O7+M7+N7+X7 -> 0 | K7: =+COUNTIFS('muddati otgan'!C:C,A7,'muddati otgan'!AA:AA,"Arizani qabul qilish") -> 0 | L7: =+COUNTIFS('muddati otgan'!C:C,A7,'muddati otgan'!J:J,"Arizani rad etish") -> 0 | M7: =+COUNTIFS('muddati otgan'!C:C,A7,'muddati otgan'!J:J,"Arizani tasdiqlash") -> 0 | N7: =+COUNTIFS('muddati otgan'!C:C,A7,'muddati otgan'!J:J,"Arizani yo'naltirish") -> 0 | O7: =+COUNTIFS('muddati otgan'!C:C,A7,'muddati otgan'!J:J,"Rad qilish sababini o'rganish") -> 0 | P7: =+COUNTIFS('muddati otgan'!C:C,A7,'muddati otgan'!J:J,"Ko'chmas mulkni UZKAD ga migratsiya qilish") -> 0 | Q7: =+COUNTIFS('muddati otgan'!C:C,A7,'muddati otgan'!J:J,"Migratisya qilingan obyekt holatini tekshirish") -> 0 | R7: =+COUNTIFS('muddati otgan'!C:C,A7,'muddati otgan'!J:J,"Ko‘chmas mulkni tanlash") -> 0 | S7: =+COUNTIFS('muddati otgan'!C:C,A7,'muddati otgan'!J:J,"Arizani ko'rib chiqish") -> 0 | T7: =+COUNTIFS('muddati otgan'!C:C,A7,'muddati otgan'!J:J,"Kadastr muhandisini tanlash") -> 0 | U7: =+COUNTIFS('muddati otgan'!C:C,A7,'muddati otgan'!J:J,"Ko'chmas mulk turini tanlahsh") -> 0 | V7: =+COUNTIFS('muddati otgan'!C:C,A7,'muddati otgan'!AA:AA,"Rad qilish") -> 0 | W7: =+COUNTIFS('muddati otgan'!C:C,A7,'muddati otgan'!J:J,"ijrochi tanlash") -> 0 | X7: =+COUNTIFS('muddati otgan'!C:C,A7,'muddati otgan'!J:J,"Ko'chmas mulk turini tanlash") -> 0 | Y7: =Z7+AD7+AF7+AE7+AC7+AB7+AA7 -> 0 | Z7: =+COUNTIFS('muddati otgan'!C:C,A7,'muddati otgan'!J:J,"Ijroga qabul qilish") -> 0 | AA7: =+COUNTIFS('muddati otgan'!C:C,A7,'muddati otgan'!J:J,"Joyida o'rganish va ma'lumotlarni kiritish") -> 0 | AB7: =+COUNTIFS('muddati otgan'!C:C,A7,'muddati otgan'!J:J,"Asosiy qismdan ajratish jarayonida") -> 0 | AC7: =+COUNTIFS('muddati otgan'!C:C,A7,'muddati otgan'!J:J,"Umumiy foydalanishdagi obyekt yaratilish") -> 0 | AD7: =+COUNTIFS('muddati otgan'!C:C,A7,'muddati otgan'!J:J,"Migratsiya qilinadigan kadastr raqamini kiritish") -> 0 | AE7: =+COUNTIFS('muddati otgan'!C:C,A7,'muddati otgan'!J:J,"O'zida qolgan obyektni yaratish") -> 0 | AF7: =+COUNTIFS('muddati otgan'!C:C,A7,'muddati otgan'!J:J,"O'lchov natijalarini kiritish") -> 0 | AG7: =+COUNTIFS('muddati otgan'!C:C,A7,'muddati otgan'!J:J,"Topoxaritani tayyorlash (dwg, pdf)") -> 0 | AH7: =AI7 -> 0 | AI7: =+COUNTIFS('muddati otgan'!C:C,A7,'muddati otgan'!J:J,"Yer uchastkasini yaratish") -> 0 | AJ7: =AK7 -> 0 | AK7: =+COUNTIFS('muddati otgan'!C:C,A7,'muddati otgan'!J:J,"Kelishish (Boshqarma)") -> 0 | AL7: =AM7+AN7+AO7 -> 0 | AM7: =+COUNTIFS('muddati otgan'!C:C,A7,'muddati otgan'!J:J,"Kelishish (DKP)") -> 0 | AN7: =+COUNTIFS('muddati otgan'!C:C,A7,'muddati otgan'!J:J,"Kelishish") -> 0 | AO7: =+COUNTIFS('muddati otgan'!C:C,A7,'muddati otgan'!J:J,"Kelishish (Registratsiya DKP)") -> 0 | AP7: =AQ7+AR7+AS7+AT7 -> 0 | AQ7: =+COUNTIFS('muddati otgan'!C:C,A7,'muddati otgan'!J:J,"Manzil biriktirish") -> 0 | AR7: =+COUNTIFS('muddati otgan'!C:C,A7,'muddati otgan'!J:J,"Bino va inshootlarni yaratish") -> 0 | AS7: =+COUNTIFS('muddati otgan'!C:C,A7,'muddati otgan'!J:J,"Dov daraxtlarni yaratish") -> 0 | AT7: =+COUNTIFS('muddati otgan'!C:C,A7,'muddati otgan'!J:J,"Yer uchastkasini tahrirlash") -> 0 | AU7: =AV7+AW7+AX7+AY7+AZ7 -> 0 | AV7: =+COUNTIFS('muddati otgan'!C:C,A7,'muddati otgan'!J:J,"Yer toifasi va maqsadini kiritish") -> 0 | AW7: =+COUNTIFS('muddati otgan'!C:C,A7,'muddati otgan'!J:J,"Auksion yer tekshirish") -> 0 | AX7: =+COUNTIFS('muddati otgan'!C:C,A7,'muddati otgan'!J:J,"Yer turlarini kiritish") -> 0 | AY7: =+COUNTIFS('muddati otgan'!C:C,A7,'muddati otgan'!J:J,"Ma'lumotlarni kiritish") -> 0 | AZ7: =+COUNTIFS('muddati otgan'!C:C,A7,'muddati otgan'!J:J,"Yer tekshirish") -> 0 | BA7: =BB7+BC7+BD7+BE7+BF7+BG7+BH7+BI7+BJ7+BK7 -> 0 | BB7: =+COUNTIFS('muddati otgan'!C:C,A7,'muddati otgan'!J:J,"Bino va inshoot ma'lumotlarini to‘ldirish") -> 0 | BC7: =+COUNTIFS('muddati otgan'!C:C,A7,'muddati otgan'!J:J,"Inventarizatsiya ma'lumotlarini to‘ldirish") -> 0 | BD7: =+COUNTIFS('muddati otgan'!C:C,A7,'muddati otgan'!J:J,"Yer uchastkasiga huquqiy hujjatlarni kiritsh") -> 0 | BE7: =+COUNTIFS('muddati otgan'!C:C,A7,'muddati otgan'!J:J,"Bino-inshootlarga huquqiy hujjatlarni kiritsh") -> 0 | BF7: =+COUNTIFS('muddati otgan'!C:C,A7,'muddati otgan'!J:J,"Kadastr qiymatini hisoblash va kiritish") -> 0 | BG7: =+COUNTIFS('muddati otgan'!C:C,A7,'muddati otgan'!J:J,"Kadastr raqam biriktirish") -> 0 | BH7: =+COUNTIFS('muddati otgan'!C:C,A7,'muddati otgan'!J:J,"Kadastr yig'ma jildni tayyorlash") -> 0 | BI7: =+COUNTIFS('muddati otgan'!C:C,A7,'muddati otgan'!J:J,"Huquqni yaratish") -> 0 | BJ7: =+COUNTIFS('muddati otgan'!C:C,A7,'muddati otgan'!J:J,"Hujjatlarni o'rganish") -> 0 | BK7: =+COUNTIFS('muddati otgan'!C:C,A7,'muddati otgan'!J:J,"Ma'lumotlarni tekshirish") -> 0 | BL7: =BM7+BN7+BP7+BO7+BQ7 -> 0 | BM7: =+COUNTIFS('muddati otgan'!C:C,A7,'muddati otgan'!J:J,"Tekshirish") -> 0 | BN7: =+COUNTIFS('muddati otgan'!C:C,A7,'muddati otgan'!J:J,"Hujjatlarni tekshirish") -> 0 | BO7: =+COUNTIFS('muddati otgan'!C:C,A7,'muddati otgan'!J:J,"Tasdiqlash") -> 0 | BP7: =+COUNTIFS('muddati otgan'!C:C,A7,'muddati otgan'!J:J,"tekshirish/tasdiqlash") -> 0 | BQ7: =+COUNTIFS('muddati otgan'!C:C,A7,'muddati otgan'!J:J,"Ma'lumotlarni tasdiqlash") -> 0 | BR7: =BS7+BU7+BV7+BW7+BX7+BY7-BT7 -> 1 | BS7: =+COUNTIFS('muddati otgan'!C:C,A7,'muddati otgan'!J:J,"Ro'yxatdan o'tkazish ma'lumotlarini tekshirish") -> 1 | BT7: =+COUNTIFS('muddati otgan'!C:C,A7,'muddati otgan'!J:J,"Kamchiliklar bo'yicha habarnoma yuborish va 3 kunga to'xtatish") -> 0 | BU7: =+COUNTIFS('muddati otgan'!C:C,A7,'muddati otgan'!J:J,"Hisobga olish") -> 0 | BV7: =+COUNTIFS('muddati otgan'!C:C,A7,'muddati otgan'!J:J,"Yer uchastkasiga huquq yaratish") -> 0 | BW7: =+COUNTIFS('muddati otgan'!C:C,A7,'muddati otgan'!J:J,"Bino-inshootga huquq yaratish") -> 0 | BX7: =+COUNTIFS('muddati otgan'!C:C,A7,'muddati otgan'!J:J,"Cheklov yaratish") -> 0 | BY7: =+COUNTIFS('muddati otgan'!C:C,A7,'muddati otgan'!J:J,"Taqiq yaratish") -> 0 | BZ7: =CA7 -> 0 | CA7: =+COUNTIFS('muddati otgan'!C:C,A7,'muddati otgan'!J:J,"Soliq maydonini tekshirish") -> 0 | CB7: =CC7 -> 0 | CC7: =+COUNTIFS('muddati otgan'!C:C,A7,'muddati otgan'!J:J,"Kadastr yig'majildini shakllantirish") -> 0 | CD7: =CE7+CF7+CG7+CI7+CJ7+CH7 -> 0 | CE7: =+COUNTIFS('muddati otgan'!C:C,A7,'muddati otgan'!J:J,"Kadastr passportini shakllantirish") -> 0 | CF7: =+COUNTIFS('muddati otgan'!C:C,A7,'muddati otgan'!J:J,"Yig'ma jildni tasdiqlash") -> 0 | CG7: =+COUNTIFS('muddati otgan'!C:C,A7,'muddati otgan'!J:J,"To'lov yoki bepul tasdiqlash") -> 0 | CH7: =+COUNTIFS('muddati otgan'!C:C,A7,'muddati otgan'!J:J,"Bog'liq arizani kutish") -> 0 | CI7: =+COUNTIFS('muddati otgan'!C:C,A7,'muddati otgan'!J:J,"To'lovga chiqarish") -> 0 | CJ7: =+COUNTIFS('muddati otgan'!C:C,A7,'muddati otgan'!J:J,"Hisobga qo'yish") -> 0 | CK7: =+COUNTIFS('muddati otgan'!C:C,A7,'muddati otgan'!J:J,"To'lov kutilmoqda") -> 2 | CL7: =CM7+CN7+CO7+CP7+CQ7+CR7+CS7+CT7 -> 0 | CM7: =+COUNTIFS('muddati otgan'!C:C,A7,'muddati otgan'!AA:AA,"Arizani qabul qilish2") -> 0 | CN7: =+COUNTIFS('muddati otgan'!C:C,A7,'muddati otgan'!J:J,"Huquqlarni tekshirish") -> 0 | CO7: =+COUNTIFS('muddati otgan'!C:C,A7,'muddati otgan'!J:J,"Ko'chmas mulkni ro'yhatdan o'tkazishga qabul qilish") -> 0 | CP7: =+COUNTIFS('muddati otgan'!C:C,A7,'muddati otgan'!J:J,"Ro'yxatdan o'tkazish") -> 0 | CQ7: =+COUNTIFS('muddati otgan'!C:C,A7,'muddati otgan'!J:J,"Kadastr pasporti va ko'chirmani yuborish") -> 0 | CR7: =+COUNTIFS('muddati otgan'!C:C,A7,'muddati otgan'!AA:AA,"Rad qilish2") -> 0 | CS7: =+COUNTIFS('muddati otgan'!C:C,A7,'muddati otgan'!J:J,"Ko'chirmani yuborish") -> 0 | CT7: =+COUNTIFS('muddati otgan'!C:C,A7,'muddati otgan'!J:J,"Ma‘lumotlarni tekshirish") -> 0 | CU7: =CV7 -> 0 | CV7: =+COUNTIFS('muddati otgan'!C:C,A7,'muddati otgan'!J:J,"Kadastr yig'majildini chop etish va arxiv ishiga tikish") -> 0 | CW7: =CX7+CY7 -> 0 | CX7: =+COUNTIFS('muddati otgan'!C:C,A7,'muddati otgan'!J:J,"Kadastr yig‘majildini qabul qilish, arizani yakunlash") -> 0 | CY7: =+COUNTIFS('muddati otgan'!C:C,A7,'muddati otgan'!J:J,"Next Cloudga yuklash") -> 0 | CZ7: =+COUNTIFS('muddati otgan'!C:C,A7,'muddati otgan'!J:J,"Kelishish kutilmoqda") -> 0 | DA7: =+COUNTIFS('muddati otgan'!C:C,A7,'muddati otgan'!J:J,"Yakunlandi") -> 0 | DB7: =+COUNTIFS('muddati otgan'!C:C,A7,'muddati otgan'!J:J,"Rad etildi") -> 0 | DC7: =CK7+CZ7+DA7+DB7-D7 -> -1 | DD7: =COUNTIFS('jami 1-20 kunlik arizalar'!C:C,A:A,'jami 1-20 kunlik arizalar'!S:S,"1") -> 0 | DE7: =COUNTIFS('jami 1-20 kunlik arizalar'!C:C,A:A,'jami 1-20 kunlik arizalar'!S:S,"2") -> 0 | DF7: =COUNTIFS('jami 1-20 kunlik arizalar'!C:C,A:A,'jami 1-20 kunlik arizalar'!S:S,"3") -> 2 | DG7: =COUNTIFS('jami 1-20 kunlik arizalar'!C:C,A:A,'jami 1-20 kunlik arizalar'!S:S,"4") -> 0 | DH7: =COUNTIFS('jami 1-20 kunlik arizalar'!C:C,A:A,'jami 1-20 kunlik arizalar'!S:S,"5") -> 1 | DI7: =SUM(COUNTIFS('jami 1-20 kunlik arizalar'!C:C,A:A, 'jami 1-20 kunlik arizalar'!S:S, {6,7,8,9,10})) -> 12 | DJ7: =SUM(COUNTIFS('jami 1-20 kunlik arizalar'!C:C,A:A, 'jami 1-20 kunlik arizalar'!S:S,">10")) -> 8
A8: 31207812190095 | C8: ABDURAXMONOV OTABEK | D8: =+COUNTIFS('muddati otgan'!C:C,A8,'muddati otgan'!C:C,A8) -> 0 | E8: =SUMIFS('muddati otgan'!$V:V,'muddati otgan'!$C:C,$A:A) -> 0 | F8: =SUMIFS('muddati otgan'!$W:W,'muddati otgan'!$C:C,$A:A) -> 0 | G8: =SUMIFS('muddati otgan'!$U:U,'muddati otgan'!$C:C,$A:A) -> 0 | H8: =SUMIFS('muddati otgan'!$G:G,'muddati otgan'!$C:C,$A:A) -> 0 | I8: =SUMIFS('muddati otgan'!$H:H,'muddati otgan'!$C:C,$A:A) -> 0 | J8: =K8+P8+Q8+R8+S8+T8+U8+V8+W8+L8+O8+M8+N8+X8 -> 0 | K8: =+COUNTIFS('muddati otgan'!C:C,A8,'muddati otgan'!AA:AA,"Arizani qabul qilish") -> 0 | L8: =+COUNTIFS('muddati otgan'!C:C,A8,'muddati otgan'!J:J,"Arizani rad etish") -> 0 | M8: =+COUNTIFS('muddati otgan'!C:C,A8,'muddati otgan'!J:J,"Arizani tasdiqlash") -> 0 | N8: =+COUNTIFS('muddati otgan'!C:C,A8,'muddati otgan'!J:J,"Arizani yo'naltirish") -> 0 | O8: =+COUNTIFS('muddati otgan'!C:C,A8,'muddati otgan'!J:J,"Rad qilish sababini o'rganish") -> 0 | P8: =+COUNTIFS('muddati otgan'!C:C,A8,'muddati otgan'!J:J,"Ko'chmas mulkni UZKAD ga migratsiya qilish") -> 0 | Q8: =+COUNTIFS('muddati otgan'!C:C,A8,'muddati otgan'!J:J,"Migratisya qilingan obyekt holatini tekshirish") -> 0 | R8: =+COUNTIFS('muddati otgan'!C:C,A8,'muddati otgan'!J:J,"Ko‘chmas mulkni tanlash") -> 0 | S8: =+COUNTIFS('muddati otgan'!C:C,A8,'muddati otgan'!J:J,"Arizani ko'rib chiqish") -> 0 | T8: =+COUNTIFS('muddati otgan'!C:C,A8,'muddati otgan'!J:J,"Kadastr muhandisini tanlash") -> 0 | U8: =+COUNTIFS('muddati otgan'!C:C,A8,'muddati otgan'!J:J,"Ko'chmas mulk turini tanlahsh") -> 0 | V8: =+COUNTIFS('muddati otgan'!C:C,A8,'muddati otgan'!AA:AA,"Rad qilish") -> 0 | W8: =+COUNTIFS('muddati otgan'!C:C,A8,'muddati otgan'!J:J,"ijrochi tanlash") -> 0 | X8: =+COUNTIFS('muddati otgan'!C:C,A8,'muddati otgan'!J:J,"Ko'chmas mulk turini tanlash") -> 0 | Y8: =Z8+AD8+AF8+AE8+AC8+AB8+AA8 -> 0 | Z8: =+COUNTIFS('muddati otgan'!C:C,A8,'muddati otgan'!J:J,"Ijroga qabul qilish") -> 0 | AA8: =+COUNTIFS('muddati otgan'!C:C,A8,'muddati otgan'!J:J,"Joyida o'rganish va ma'lumotlarni kiritish") -> 0 | AB8: =+COUNTIFS('muddati otgan'!C:C,A8,'muddati otgan'!J:J,"Asosiy qismdan ajratish jarayonida") -> 0 | AC8: =+COUNTIFS('muddati otgan'!C:C,A8,'muddati otgan'!J:J,"Umumiy foydalanishdagi obyekt yaratilish") -> 0 | AD8: =+COUNTIFS('muddati otgan'!C:C,A8,'muddati otgan'!J:J,"Migratsiya qilinadigan kadastr raqamini kiritish") -> 0 | AE8: =+COUNTIFS('muddati otgan'!C:C,A8,'muddati otgan'!J:J,"O'zida qolgan obyektni yaratish") -> 0 | AF8: =+COUNTIFS('muddati otgan'!C:C,A8,'muddati otgan'!J:J,"O'lchov natijalarini kiritish") -> 0 | AG8: =+COUNTIFS('muddati otgan'!C:C,A8,'muddati otgan'!J:J,"Topoxaritani tayyorlash (dwg, pdf)") -> 0 | AH8: =AI8 -> 0 | AI8: =+COUNTIFS('muddati otgan'!C:C,A8,'muddati otgan'!J:J,"Yer uchastkasini yaratish") -> 0 | AJ8: =AK8 -> 0 | AK8: =+COUNTIFS('muddati otgan'!C:C,A8,'muddati otgan'!J:J,"Kelishish (Boshqarma)") -> 0 | AL8: =AM8+AN8+AO8 -> 0 | AM8: =+COUNTIFS('muddati otgan'!C:C,A8,'muddati otgan'!J:J,"Kelishish (DKP)") -> 0 | AN8: =+COUNTIFS('muddati otgan'!C:C,A8,'muddati otgan'!J:J,"Kelishish") -> 0 | AO8: =+COUNTIFS('muddati otgan'!C:C,A8,'muddati otgan'!J:J,"Kelishish (Registratsiya DKP)") -> 0 | AP8: =AQ8+AR8+AS8+AT8 -> 0 | AQ8: =+COUNTIFS('muddati otgan'!C:C,A8,'muddati otgan'!J:J,"Manzil biriktirish") -> 0 | AR8: =+COUNTIFS('muddati otgan'!C:C,A8,'muddati otgan'!J:J,"Bino va inshootlarni yaratish") -> 0 | AS8: =+COUNTIFS('muddati otgan'!C:C,A8,'muddati otgan'!J:J,"Dov daraxtlarni yaratish") -> 0 | AT8: =+COUNTIFS('muddati otgan'!C:C,A8,'muddati otgan'!J:J,"Yer uchastkasini tahrirlash") -> 0 | AU8: =AV8+AW8+AX8+AY8+AZ8 -> 0 | AV8: =+COUNTIFS('muddati otgan'!C:C,A8,'muddati otgan'!J:J,"Yer toifasi va maqsadini kiritish") -> 0 | AW8: =+COUNTIFS('muddati otgan'!C:C,A8,'muddati otgan'!J:J,"Auksion yer tekshirish") -> 0 | AX8: =+COUNTIFS('muddati otgan'!C:C,A8,'muddati otgan'!J:J,"Yer turlarini kiritish") -> 0 | AY8: =+COUNTIFS('muddati otgan'!C:C,A8,'muddati otgan'!J:J,"Ma'lumotlarni kiritish") -> 0 | AZ8: =+COUNTIFS('muddati otgan'!C:C,A8,'muddati otgan'!J:J,"Yer tekshirish") -> 0 | BA8: =BB8+BC8+BD8+BE8+BF8+BG8+BH8+BI8+BJ8+BK8 -> 0 | BB8: =+COUNTIFS('muddati otgan'!C:C,A8,'muddati otgan'!J:J,"Bino va inshoot ma'lumotlarini to‘ldirish") -> 0 | BC8: =+COUNTIFS('muddati otgan'!C:C,A8,'muddati otgan'!J:J,"Inventarizatsiya ma'lumotlarini to‘ldirish") -> 0 | BD8: =+COUNTIFS('muddati otgan'!C:C,A8,'muddati otgan'!J:J,"Yer uchastkasiga huquqiy hujjatlarni kiritsh") -> 0 | BE8: =+COUNTIFS('muddati otgan'!C:C,A8,'muddati otgan'!J:J,"Bino-inshootlarga huquqiy hujjatlarni kiritsh") -> 0 | BF8: =+COUNTIFS('muddati otgan'!C:C,A8,'muddati otgan'!J:J,"Kadastr qiymatini hisoblash va kiritish") -> 0 | BG8: =+COUNTIFS('muddati otgan'!C:C,A8,'muddati otgan'!J:J,"Kadastr raqam biriktirish") -> 0 | BH8: =+COUNTIFS('muddati otgan'!C:C,A8,'muddati otgan'!J:J,"Kadastr yig'ma jildni tayyorlash") -> 0 | BI8: =+COUNTIFS('muddati otgan'!C:C,A8,'muddati otgan'!J:J,"Huquqni yaratish") -> 0 | BJ8: =+COUNTIFS('muddati otgan'!C:C,A8,'muddati otgan'!J:J,"Hujjatlarni o'rganish") -> 0 | BK8: =+COUNTIFS('muddati otgan'!C:C,A8,'muddati otgan'!J:J,"Ma'lumotlarni tekshirish") -> 0 | BL8: =BM8+BN8+BP8+BO8+BQ8 -> 0 | BM8: =+COUNTIFS('muddati otgan'!C:C,A8,'muddati otgan'!J:J,"Tekshirish") -> 0 | BN8: =+COUNTIFS('muddati otgan'!C:C,A8,'muddati otgan'!J:J,"Hujjatlarni tekshirish") -> 0 | BO8: =+COUNTIFS('muddati otgan'!C:C,A8,'muddati otgan'!J:J,"Tasdiqlash") -> 0 | BP8: =+COUNTIFS('muddati otgan'!C:C,A8,'muddati otgan'!J:J,"tekshirish/tasdiqlash") -> 0 | BQ8: =+COUNTIFS('muddati otgan'!C:C,A8,'muddati otgan'!J:J,"Ma'lumotlarni tasdiqlash") -> 0 | BR8: =BS8+BU8+BV8+BW8+BX8+BY8-BT8 -> 0 | BS8: =+COUNTIFS('muddati otgan'!C:C,A8,'muddati otgan'!J:J,"Ro'yxatdan o'tkazish ma'lumotlarini tekshirish") -> 0 | BT8: =+COUNTIFS('muddati otgan'!C:C,A8,'muddati otgan'!J:J,"Kamchiliklar bo'yicha habarnoma yuborish va 3 kunga to'xtatish") -> 0 | BU8: =+COUNTIFS('muddati otgan'!C:C,A8,'muddati otgan'!J:J,"Hisobga olish") -> 0 | BV8: =+COUNTIFS('muddati otgan'!C:C,A8,'muddati otgan'!J:J,"Yer uchastkasiga huquq yaratish") -> 0 | BW8: =+COUNTIFS('muddati otgan'!C:C,A8,'muddati otgan'!J:J,"Bino-inshootga huquq yaratish") -> 0 | BX8: =+COUNTIFS('muddati otgan'!C:C,A8,'muddati otgan'!J:J,"Cheklov yaratish") -> 0 | BY8: =+COUNTIFS('muddati otgan'!C:C,A8,'muddati otgan'!J:J,"Taqiq yaratish") -> 0 | BZ8: =CA8 -> 0 | CA8: =+COUNTIFS('muddati otgan'!C:C,A8,'muddati otgan'!J:J,"Soliq maydonini tekshirish") -> 0 | CB8: =CC8 -> 0 | CC8: =+COUNTIFS('muddati otgan'!C:C,A8,'muddati otgan'!J:J,"Kadastr yig'majildini shakllantirish") -> 0 | CD8: =CE8+CF8+CG8+CI8+CJ8+CH8 -> 0 | CE8: =+COUNTIFS('muddati otgan'!C:C,A8,'muddati otgan'!J:J,"Kadastr passportini shakllantirish") -> 0 | CF8: =+COUNTIFS('muddati otgan'!C:C,A8,'muddati otgan'!J:J,"Yig'ma jildni tasdiqlash") -> 0 | CG8: =+COUNTIFS('muddati otgan'!C:C,A8,'muddati otgan'!J:J,"To'lov yoki bepul tasdiqlash") -> 0 | CH8: =+COUNTIFS('muddati otgan'!C:C,A8,'muddati otgan'!J:J,"Bog'liq arizani kutish") -> 0 | CI8: =+COUNTIFS('muddati otgan'!C:C,A8,'muddati otgan'!J:J,"To'lovga chiqarish") -> 0 | CJ8: =+COUNTIFS('muddati otgan'!C:C,A8,'muddati otgan'!J:J,"Hisobga qo'yish") -> 0 | CK8: =+COUNTIFS('muddati otgan'!C:C,A8,'muddati otgan'!J:J,"To'lov kutilmoqda") -> 0 | CL8: =CM8+CN8+CO8+CP8+CQ8+CR8+CS8+CT8 -> 0 | CM8: =+COUNTIFS('muddati otgan'!C:C,A8,'muddati otgan'!AA:AA,"Arizani qabul qilish2") -> 0 | CN8: =+COUNTIFS('muddati otgan'!C:C,A8,'muddati otgan'!J:J,"Huquqlarni tekshirish") -> 0 | CO8: =+COUNTIFS('muddati otgan'!C:C,A8,'muddati otgan'!J:J,"Ko'chmas mulkni ro'yhatdan o'tkazishga qabul qilish") -> 0 | CP8: =+COUNTIFS('muddati otgan'!C:C,A8,'muddati otgan'!J:J,"Ro'yxatdan o'tkazish") -> 0 | CQ8: =+COUNTIFS('muddati otgan'!C:C,A8,'muddati otgan'!J:J,"Kadastr pasporti va ko'chirmani yuborish") -> 0 | CR8: =+COUNTIFS('muddati otgan'!C:C,A8,'muddati otgan'!AA:AA,"Rad qilish2") -> 0 | CS8: =+COUNTIFS('muddati otgan'!C:C,A8,'muddati otgan'!J:J,"Ko'chirmani yuborish") -> 0 | CT8: =+COUNTIFS('muddati otgan'!C:C,A8,'muddati otgan'!J:J,"Ma‘lumotlarni tekshirish") -> 0 | CU8: =CV8 -> 0 | CV8: =+COUNTIFS('muddati otgan'!C:C,A8,'muddati otgan'!J:J,"Kadastr yig'majildini chop etish va arxiv ishiga tikish") -> 0 | CW8: =CX8+CY8 -> 0 | CX8: =+COUNTIFS('muddati otgan'!C:C,A8,'muddati otgan'!J:J,"Kadastr yig‘majildini qabul qilish, arizani yakunlash") -> 0 | CY8: =+COUNTIFS('muddati otgan'!C:C,A8,'muddati otgan'!J:J,"Next Cloudga yuklash") -> 0 | CZ8: =+COUNTIFS('muddati otgan'!C:C,A8,'muddati otgan'!J:J,"Kelishish kutilmoqda") -> 0 | DA8: =+COUNTIFS('muddati otgan'!C:C,A8,'muddati otgan'!J:J,"Yakunlandi") -> 0 | DB8: =+COUNTIFS('muddati otgan'!C:C,A8,'muddati otgan'!J:J,"Rad etildi") -> 0 | DC8: =CK8+CZ8+DA8+DB8-D8 -> 0 | DD8: =COUNTIFS('jami 1-20 kunlik arizalar'!C:C,A:A,'jami 1-20 kunlik arizalar'!S:S,"1") -> 0 | DE8: =COUNTIFS('jami 1-20 kunlik arizalar'!C:C,A:A,'jami 1-20 kunlik arizalar'!S:S,"2") -> 0 | DF8: =COUNTIFS('jami 1-20 kunlik arizalar'!C:C,A:A,'jami 1-20 kunlik arizalar'!S:S,"3") -> 0 | DG8: =COUNTIFS('jami 1-20 kunlik arizalar'!C:C,A:A,'jami 1-20 kunlik arizalar'!S:S,"4") -> 0 | DH8: =COUNTIFS('jami 1-20 kunlik arizalar'!C:C,A:A,'jami 1-20 kunlik arizalar'!S:S,"5") -> 0 | DI8: =SUM(COUNTIFS('jami 1-20 kunlik arizalar'!C:C,A:A, 'jami 1-20 kunlik arizalar'!S:S, {6,7,8,9,10})) -> 0 | DJ8: =SUM(COUNTIFS('jami 1-20 kunlik arizalar'!C:C,A:A, 'jami 1-20 kunlik arizalar'!S:S,">10")) -> 0
A9: 31611995980026 | C9: AHADXONOV HUSANXON | D9: =+COUNTIFS('muddati otgan'!C:C,A9,'muddati otgan'!C:C,A9) -> 4 | E9: =SUMIFS('muddati otgan'!$V:V,'muddati otgan'!$C:C,$A:A) -> 0 | F9: =SUMIFS('muddati otgan'!$W:W,'muddati otgan'!$C:C,$A:A) -> 0 | G9: =SUMIFS('muddati otgan'!$U:U,'muddati otgan'!$C:C,$A:A) -> 4 | H9: =SUMIFS('muddati otgan'!$G:G,'muddati otgan'!$C:C,$A:A) -> 2 | I9: =SUMIFS('muddati otgan'!$H:H,'muddati otgan'!$C:C,$A:A) -> 2 | J9: =K9+P9+Q9+R9+S9+T9+U9+V9+W9+L9+O9+M9+N9+X9 -> 0 | K9: =+COUNTIFS('muddati otgan'!C:C,A9,'muddati otgan'!AA:AA,"Arizani qabul qilish") -> 0 | L9: =+COUNTIFS('muddati otgan'!C:C,A9,'muddati otgan'!J:J,"Arizani rad etish") -> 0 | M9: =+COUNTIFS('muddati otgan'!C:C,A9,'muddati otgan'!J:J,"Arizani tasdiqlash") -> 0 | N9: =+COUNTIFS('muddati otgan'!C:C,A9,'muddati otgan'!J:J,"Arizani yo'naltirish") -> 0 | O9: =+COUNTIFS('muddati otgan'!C:C,A9,'muddati otgan'!J:J,"Rad qilish sababini o'rganish") -> 0 | P9: =+COUNTIFS('muddati otgan'!C:C,A9,'muddati otgan'!J:J,"Ko'chmas mulkni UZKAD ga migratsiya qilish") -> 0 | Q9: =+COUNTIFS('muddati otgan'!C:C,A9,'muddati otgan'!J:J,"Migratisya qilingan obyekt holatini tekshirish") -> 0 | R9: =+COUNTIFS('muddati otgan'!C:C,A9,'muddati otgan'!J:J,"Ko‘chmas mulkni tanlash") -> 0 | S9: =+COUNTIFS('muddati otgan'!C:C,A9,'muddati otgan'!J:J,"Arizani ko'rib chiqish") -> 0 | T9: =+COUNTIFS('muddati otgan'!C:C,A9,'muddati otgan'!J:J,"Kadastr muhandisini tanlash") -> 0 | U9: =+COUNTIFS('muddati otgan'!C:C,A9,'muddati otgan'!J:J,"Ko'chmas mulk turini tanlahsh") -> 0 | V9: =+COUNTIFS('muddati otgan'!C:C,A9,'muddati otgan'!AA:AA,"Rad qilish") -> 0 | W9: =+COUNTIFS('muddati otgan'!C:C,A9,'muddati otgan'!J:J,"ijrochi tanlash") -> 0 | X9: =+COUNTIFS('muddati otgan'!C:C,A9,'muddati otgan'!J:J,"Ko'chmas mulk turini tanlash") -> 0 | Y9: =Z9+AD9+AF9+AE9+AC9+AB9+AA9 -> 0 | Z9: =+COUNTIFS('muddati otgan'!C:C,A9,'muddati otgan'!J:J,"Ijroga qabul qilish") -> 0 | AA9: =+COUNTIFS('muddati otgan'!C:C,A9,'muddati otgan'!J:J,"Joyida o'rganish va ma'lumotlarni kiritish") -> 0 | AB9: =+COUNTIFS('muddati otgan'!C:C,A9,'muddati otgan'!J:J,"Asosiy qismdan ajratish jarayonida") -> 0 | AC9: =+COUNTIFS('muddati otgan'!C:C,A9,'muddati otgan'!J:J,"Umumiy foydalanishdagi obyekt yaratilish") -> 0 | AD9: =+COUNTIFS('muddati otgan'!C:C,A9,'muddati otgan'!J:J,"Migratsiya qilinadigan kadastr raqamini kiritish") -> 0 | AE9: =+COUNTIFS('muddati otgan'!C:C,A9,'muddati otgan'!J:J,"O'zida qolgan obyektni yaratish") -> 0 | AF9: =+COUNTIFS('muddati otgan'!C:C,A9,'muddati otgan'!J:J,"O'lchov natijalarini kiritish") -> 0 | AG9: =+COUNTIFS('muddati otgan'!C:C,A9,'muddati otgan'!J:J,"Topoxaritani tayyorlash (dwg, pdf)") -> 0 | AH9: =AI9 -> 0 | AI9: =+COUNTIFS('muddati otgan'!C:C,A9,'muddati otgan'!J:J,"Yer uchastkasini yaratish") -> 0 | AJ9: =AK9 -> 0 | AK9: =+COUNTIFS('muddati otgan'!C:C,A9,'muddati otgan'!J:J,"Kelishish (Boshqarma)") -> 0 | AL9: =AM9+AN9+AO9 -> 0 | AM9: =+COUNTIFS('muddati otgan'!C:C,A9,'muddati otgan'!J:J,"Kelishish (DKP)") -> 0 | AN9: =+COUNTIFS('muddati otgan'!C:C,A9,'muddati otgan'!J:J,"Kelishish") -> 0 | AO9: =+COUNTIFS('muddati otgan'!C:C,A9,'muddati otgan'!J:J,"Kelishish (Registratsiya DKP)") -> 0 | AP9: =AQ9+AR9+AS9+AT9 -> 0 | AQ9: =+COUNTIFS('muddati otgan'!C:C,A9,'muddati otgan'!J:J,"Manzil biriktirish") -> 0 | AR9: =+COUNTIFS('muddati otgan'!C:C,A9,'muddati otgan'!J:J,"Bino va inshootlarni yaratish") -> 0 | AS9: =+COUNTIFS('muddati otgan'!C:C,A9,'muddati otgan'!J:J,"Dov daraxtlarni yaratish") -> 0 | AT9: =+COUNTIFS('muddati otgan'!C:C,A9,'muddati otgan'!J:J,"Yer uchastkasini tahrirlash") -> 0 | AU9: =AV9+AW9+AX9+AY9+AZ9 -> 0 | AV9: =+COUNTIFS('muddati otgan'!C:C,A9,'muddati otgan'!J:J,"Yer toifasi va maqsadini kiritish") -> 0 | AW9: =+COUNTIFS('muddati otgan'!C:C,A9,'muddati otgan'!J:J,"Auksion yer tekshirish") -> 0 | AX9: =+COUNTIFS('muddati otgan'!C:C,A9,'muddati otgan'!J:J,"Yer turlarini kiritish") -> 0 | AY9: =+COUNTIFS('muddati otgan'!C:C,A9,'muddati otgan'!J:J,"Ma'lumotlarni kiritish") -> 0 | AZ9: =+COUNTIFS('muddati otgan'!C:C,A9,'muddati otgan'!J:J,"Yer tekshirish") -> 0 | BA9: =BB9+BC9+BD9+BE9+BF9+BG9+BH9+BI9+BJ9+BK9 -> 0 | BB9: =+COUNTIFS('muddati otgan'!C:C,A9,'muddati otgan'!J:J,"Bino va inshoot ma'lumotlarini to‘ldirish") -> 0 | BC9: =+COUNTIFS('muddati otgan'!C:C,A9,'muddati otgan'!J:J,"Inventarizatsiya ma'lumotlarini to‘ldirish") -> 0 | BD9: =+COUNTIFS('muddati otgan'!C:C,A9,'muddati otgan'!J:J,"Yer uchastkasiga huquqiy hujjatlarni kiritsh") -> 0 | BE9: =+COUNTIFS('muddati otgan'!C:C,A9,'muddati otgan'!J:J,"Bino-inshootlarga huquqiy hujjatlarni kiritsh") -> 0 | BF9: =+COUNTIFS('muddati otgan'!C:C,A9,'muddati otgan'!J:J,"Kadastr qiymatini hisoblash va kiritish") -> 0 | BG9: =+COUNTIFS('muddati otgan'!C:C,A9,'muddati otgan'!J:J,"Kadastr raqam biriktirish") -> 0 | BH9: =+COUNTIFS('muddati otgan'!C:C,A9,'muddati otgan'!J:J,"Kadastr yig'ma jildni tayyorlash") -> 0 | BI9: =+COUNTIFS('muddati otgan'!C:C,A9,'muddati otgan'!J:J,"Huquqni yaratish") -> 0 | BJ9: =+COUNTIFS('muddati otgan'!C:C,A9,'muddati otgan'!J:J,"Hujjatlarni o'rganish") -> 0 | BK9: =+COUNTIFS('muddati otgan'!C:C,A9,'muddati otgan'!J:J,"Ma'lumotlarni tekshirish") -> 0 | BL9: =BM9+BN9+BP9+BO9+BQ9 -> 0 | BM9: =+COUNTIFS('muddati otgan'!C:C,A9,'muddati otgan'!J:J,"Tekshirish") -> 0 | BN9: =+COUNTIFS('muddati otgan'!C:C,A9,'muddati otgan'!J:J,"Hujjatlarni tekshirish") -> 0 | BO9: =+COUNTIFS('muddati otgan'!C:C,A9,'muddati otgan'!J:J,"Tasdiqlash") -> 0 | BP9: =+COUNTIFS('muddati otgan'!C:C,A9,'muddati otgan'!J:J,"tekshirish/tasdiqlash") -> 0 | BQ9: =+COUNTIFS('muddati otgan'!C:C,A9,'muddati otgan'!J:J,"Ma'lumotlarni tasdiqlash") -> 0 | BR9: =BS9+BU9+BV9+BW9+BX9+BY9-BT9 -> 0 | BS9: =+COUNTIFS('muddati otgan'!C:C,A9,'muddati otgan'!J:J,"Ro'yxatdan o'tkazish ma'lumotlarini tekshirish") -> 0 | BT9: =+COUNTIFS('muddati otgan'!C:C,A9,'muddati otgan'!J:J,"Kamchiliklar bo'yicha habarnoma yuborish va 3 kunga to'xtatish") -> 0 | BU9: =+COUNTIFS('muddati otgan'!C:C,A9,'muddati otgan'!J:J,"Hisobga olish") -> 0 | BV9: =+COUNTIFS('muddati otgan'!C:C,A9,'muddati otgan'!J:J,"Yer uchastkasiga huquq yaratish") -> 0 | BW9: =+COUNTIFS('muddati otgan'!C:C,A9,'muddati otgan'!J:J,"Bino-inshootga huquq yaratish") -> 0 | BX9: =+COUNTIFS('muddati otgan'!C:C,A9,'muddati otgan'!J:J,"Cheklov yaratish") -> 0 | BY9: =+COUNTIFS('muddati otgan'!C:C,A9,'muddati otgan'!J:J,"Taqiq yaratish") -> 0 | BZ9: =CA9 -> 0 | CA9: =+COUNTIFS('muddati otgan'!C:C,A9,'muddati otgan'!J:J,"Soliq maydonini tekshirish") -> 0 | CB9: =CC9 -> 0 | CC9: =+COUNTIFS('muddati otgan'!C:C,A9,'muddati otgan'!J:J,"Kadastr yig'majildini shakllantirish") -> 0 | CD9: =CE9+CF9+CG9+CI9+CJ9+CH9 -> 0 | CE9: =+COUNTIFS('muddati otgan'!C:C,A9,'muddati otgan'!J:J,"Kadastr passportini shakllantirish") -> 0 | CF9: =+COUNTIFS('muddati otgan'!C:C,A9,'muddati otgan'!J:J,"Yig'ma jildni tasdiqlash") -> 0 | CG9: =+COUNTIFS('muddati otgan'!C:C,A9,'muddati otgan'!J:J,"To'lov yoki bepul tasdiqlash") -> 0 | CH9: =+COUNTIFS('muddati otgan'!C:C,A9,'muddati otgan'!J:J,"Bog'liq arizani kutish") -> 0 | CI9: =+COUNTIFS('muddati otgan'!C:C,A9,'muddati otgan'!J:J,"To'lovga chiqarish") -> 0 | CJ9: =+COUNTIFS('muddati otgan'!C:C,A9,'muddati otgan'!J:J,"Hisobga qo'yish") -> 0 | CK9: =+COUNTIFS('muddati otgan'!C:C,A9,'muddati otgan'!J:J,"To'lov kutilmoqda") -> 3 | CL9: =CM9+CN9+CO9+CP9+CQ9+CR9+CS9+CT9 -> 0 | CM9: =+COUNTIFS('muddati otgan'!C:C,A9,'muddati otgan'!AA:AA,"Arizani qabul qilish2") -> 0 | CN9: =+COUNTIFS('muddati otgan'!C:C,A9,'muddati otgan'!J:J,"Huquqlarni tekshirish") -> 0 | CO9: =+COUNTIFS('muddati otgan'!C:C,A9,'muddati otgan'!J:J,"Ko'chmas mulkni ro'yhatdan o'tkazishga qabul qilish") -> 0 | CP9: =+COUNTIFS('muddati otgan'!C:C,A9,'muddati otgan'!J:J,"Ro'yxatdan o'tkazish") -> 0 | CQ9: =+COUNTIFS('muddati otgan'!C:C,A9,'muddati otgan'!J:J,"Kadastr pasporti va ko'chirmani yuborish") -> 0 | CR9: =+COUNTIFS('muddati otgan'!C:C,A9,'muddati otgan'!AA:AA,"Rad qilish2") -> 0 | CS9: =+COUNTIFS('muddati otgan'!C:C,A9,'muddati otgan'!J:J,"Ko'chirmani yuborish") -> 0 | CT9: =+COUNTIFS('muddati otgan'!C:C,A9,'muddati otgan'!J:J,"Ma‘lumotlarni tekshirish") -> 0 | CU9: =CV9 -> 0 | CV9: =+COUNTIFS('muddati otgan'!C:C,A9,'muddati otgan'!J:J,"Kadastr yig'majildini chop etish va arxiv ishiga tikish") -> 0 | CW9: =CX9+CY9 -> 0 | CX9: =+COUNTIFS('muddati otgan'!C:C,A9,'muddati otgan'!J:J,"Kadastr yig‘majildini qabul qilish, arizani yakunlash") -> 0 | CY9: =+COUNTIFS('muddati otgan'!C:C,A9,'muddati otgan'!J:J,"Next Cloudga yuklash") -> 0 | CZ9: =+COUNTIFS('muddati otgan'!C:C,A9,'muddati otgan'!J:J,"Kelishish kutilmoqda") -> 0 | DA9: =+COUNTIFS('muddati otgan'!C:C,A9,'muddati otgan'!J:J,"Yakunlandi") -> 1 | DB9: =+COUNTIFS('muddati otgan'!C:C,A9,'muddati otgan'!J:J,"Rad etildi") -> 0 | DC9: =CK9+CZ9+DA9+DB9-D9 -> 0 | DD9: =COUNTIFS('jami 1-20 kunlik arizalar'!C:C,A:A,'jami 1-20 kunlik arizalar'!S:S,"1") -> 0 | DE9: =COUNTIFS('jami 1-20 kunlik arizalar'!C:C,A:A,'jami 1-20 kunlik arizalar'!S:S,"2") -> 0 | DF9: =COUNTIFS('jami 1-20 kunlik arizalar'!C:C,A:A,'jami 1-20 kunlik arizalar'!S:S,"3") -> 5 | DG9: =COUNTIFS('jami 1-20 kunlik arizalar'!C:C,A:A,'jami 1-20 kunlik arizalar'!S:S,"4") -> 0 | DH9: =COUNTIFS('jami 1-20 kunlik arizalar'!C:C,A:A,'jami 1-20 kunlik arizalar'!S:S,"5") -> 3 | DI9: =SUM(COUNTIFS('jami 1-20 kunlik arizalar'!C:C,A:A, 'jami 1-20 kunlik arizalar'!S:S, {6,7,8,9,10})) -> 8 | DJ9: =SUM(COUNTIFS('jami 1-20 kunlik arizalar'!C:C,A:A, 'jami 1-20 kunlik arizalar'!S:S,">10")) -> 8
A10: 32910975980025 | C10: ASHRABOV NIZOMJON | D10: =+COUNTIFS('muddati otgan'!C:C,A10,'muddati otgan'!C:C,A10) -> 3 | E10: =SUMIFS('muddati otgan'!$V:V,'muddati otgan'!$C:C,$A:A) -> 0 | F10: =SUMIFS('muddati otgan'!$W:W,'muddati otgan'!$C:C,$A:A) -> 0 | G10: =SUMIFS('muddati otgan'!$U:U,'muddati otgan'!$C:C,$A:A) -> 3 | H10: =SUMIFS('muddati otgan'!$G:G,'muddati otgan'!$C:C,$A:A) -> 1 | I10: =SUMIFS('muddati otgan'!$H:H,'muddati otgan'!$C:C,$A:A) -> 2 | J10: =K10+P10+Q10+R10+S10+T10+U10+V10+W10+L10+O10+M10+N10+X10 -> 0 | K10: =+COUNTIFS('muddati otgan'!C:C,A10,'muddati otgan'!AA:AA,"Arizani qabul qilish") -> 0 | L10: =+COUNTIFS('muddati otgan'!C:C,A10,'muddati otgan'!J:J,"Arizani rad etish") -> 0 | M10: =+COUNTIFS('muddati otgan'!C:C,A10,'muddati otgan'!J:J,"Arizani tasdiqlash") -> 0 | N10: =+COUNTIFS('muddati otgan'!C:C,A10,'muddati otgan'!J:J,"Arizani yo'naltirish") -> 0 | O10: =+COUNTIFS('muddati otgan'!C:C,A10,'muddati otgan'!J:J,"Rad qilish sababini o'rganish") -> 0 | P10: =+COUNTIFS('muddati otgan'!C:C,A10,'muddati otgan'!J:J,"Ko'chmas mulkni UZKAD ga migratsiya qilish") -> 0 | Q10: =+COUNTIFS('muddati otgan'!C:C,A10,'muddati otgan'!J:J,"Migratisya qilingan obyekt holatini tekshirish") -> 0 | R10: =+COUNTIFS('muddati otgan'!C:C,A10,'muddati otgan'!J:J,"Ko‘chmas mulkni tanlash") -> 0 | S10: =+COUNTIFS('muddati otgan'!C:C,A10,'muddati otgan'!J:J,"Arizani ko'rib chiqish") -> 0 | T10: =+COUNTIFS('muddati otgan'!C:C,A10,'muddati otgan'!J:J,"Kadastr muhandisini tanlash") -> 0 | U10: =+COUNTIFS('muddati otgan'!C:C,A10,'muddati otgan'!J:J,"Ko'chmas mulk turini tanlahsh") -> 0 | V10: =+COUNTIFS('muddati otgan'!C:C,A10,'muddati otgan'!AA:AA,"Rad qilish") -> 0 | W10: =+COUNTIFS('muddati otgan'!C:C,A10,'muddati otgan'!J:J,"ijrochi tanlash") -> 0 | X10: =+COUNTIFS('muddati otgan'!C:C,A10,'muddati otgan'!J:J,"Ko'chmas mulk turini tanlash") -> 0 | Y10: =Z10+AD10+AF10+AE10+AC10+AB10+AA10 -> 0 | Z10: =+COUNTIFS('muddati otgan'!C:C,A10,'muddati otgan'!J:J,"Ijroga qabul qilish") -> 0 | AA10: =+COUNTIFS('muddati otgan'!C:C,A10,'muddati otgan'!J:J,"Joyida o'rganish va ma'lumotlarni kiritish") -> 0 | AB10: =+COUNTIFS('muddati otgan'!C:C,A10,'muddati otgan'!J:J,"Asosiy qismdan ajratish jarayonida") -> 0 | AC10: =+COUNTIFS('muddati otgan'!C:C,A10,'muddati otgan'!J:J,"Umumiy foydalanishdagi obyekt yaratilish") -> 0 | AD10: =+COUNTIFS('muddati otgan'!C:C,A10,'muddati otgan'!J:J,"Migratsiya qilinadigan kadastr raqamini kiritish") -> 0 | AE10: =+COUNTIFS('muddati otgan'!C:C,A10,'muddati otgan'!J:J,"O'zida qolgan obyektni yaratish") -> 0 | AF10: =+COUNTIFS('muddati otgan'!C:C,A10,'muddati otgan'!J:J,"O'lchov natijalarini kiritish") -> 0 | AG10: =+COUNTIFS('muddati otgan'!C:C,A10,'muddati otgan'!J:J,"Topoxaritani tayyorlash (dwg, pdf)") -> 0 | AH10: =AI10 -> 0 | AI10: =+COUNTIFS('muddati otgan'!C:C,A10,'muddati otgan'!J:J,"Yer uchastkasini yaratish") -> 0 | AJ10: =AK10 -> 0 | AK10: =+COUNTIFS('muddati otgan'!C:C,A10,'muddati otgan'!J:J,"Kelishish (Boshqarma)") -> 0 | AL10: =AM10+AN10+AO10 -> 0 | AM10: =+COUNTIFS('muddati otgan'!C:C,A10,'muddati otgan'!J:J,"Kelishish (DKP)") -> 0 | AN10: =+COUNTIFS('muddati otgan'!C:C,A10,'muddati otgan'!J:J,"Kelishish") -> 0 | AO10: =+COUNTIFS('muddati otgan'!C:C,A10,'muddati otgan'!J:J,"Kelishish (Registratsiya DKP)") -> 0 | AP10: =AQ10+AR10+AS10+AT10 -> 0 | AQ10: =+COUNTIFS('muddati otgan'!C:C,A10,'muddati otgan'!J:J,"Manzil biriktirish") -> 0 | AR10: =+COUNTIFS('muddati otgan'!C:C,A10,'muddati otgan'!J:J,"Bino va inshootlarni yaratish") -> 0 | AS10: =+COUNTIFS('muddati otgan'!C:C,A10,'muddati otgan'!J:J,"Dov daraxtlarni yaratish") -> 0 | AT10: =+COUNTIFS('muddati otgan'!C:C,A10,'muddati otgan'!J:J,"Yer uchastkasini tahrirlash") -> 0 | AU10: =AV10+AW10+AX10+AY10+AZ10 -> 0 | AV10: =+COUNTIFS('muddati otgan'!C:C,A10,'muddati otgan'!J:J,"Yer toifasi va maqsadini kiritish") -> 0 | AW10: =+COUNTIFS('muddati otgan'!C:C,A10,'muddati otgan'!J:J,"Auksion yer tekshirish") -> 0 | AX10: =+COUNTIFS('muddati otgan'!C:C,A10,'muddati otgan'!J:J,"Yer turlarini kiritish") -> 0 | AY10: =+COUNTIFS('muddati otgan'!C:C,A10,'muddati otgan'!J:J,"Ma'lumotlarni kiritish") -> 0 | AZ10: =+COUNTIFS('muddati otgan'!C:C,A10,'muddati otgan'!J:J,"Yer tekshirish") -> 0 | BA10: =BB10+BC10+BD10+BE10+BF10+BG10+BH10+BI10+BJ10+BK10 -> 0 | BB10: =+COUNTIFS('muddati otgan'!C:C,A10,'muddati otgan'!J:J,"Bino va inshoot ma'lumotlarini to‘ldirish") -> 0 | BC10: =+COUNTIFS('muddati otgan'!C:C,A10,'muddati otgan'!J:J,"Inventarizatsiya ma'lumotlarini to‘ldirish") -> 0 | BD10: =+COUNTIFS('muddati otgan'!C:C,A10,'muddati otgan'!J:J,"Yer uchastkasiga huquqiy hujjatlarni kiritsh") -> 0 | BE10: =+COUNTIFS('muddati otgan'!C:C,A10,'muddati otgan'!J:J,"Bino-inshootlarga huquqiy hujjatlarni kiritsh") -> 0 | BF10: =+COUNTIFS('muddati otgan'!C:C,A10,'muddati otgan'!J:J,"Kadastr qiymatini hisoblash va kiritish") -> 0 | BG10: =+COUNTIFS('muddati otgan'!C:C,A10,'muddati otgan'!J:J,"Kadastr raqam biriktirish") -> 0 | BH10: =+COUNTIFS('muddati otgan'!C:C,A10,'muddati otgan'!J:J,"Kadastr yig'ma jildni tayyorlash") -> 0 | BI10: =+COUNTIFS('muddati otgan'!C:C,A10,'muddati otgan'!J:J,"Huquqni yaratish") -> 0 | BJ10: =+COUNTIFS('muddati otgan'!C:C,A10,'muddati otgan'!J:J,"Hujjatlarni o'rganish") -> 0 | BK10: =+COUNTIFS('muddati otgan'!C:C,A10,'muddati otgan'!J:J,"Ma'lumotlarni tekshirish") -> 0 | BL10: =BM10+BN10+BP10+BO10+BQ10 -> 0 | BM10: =+COUNTIFS('muddati otgan'!C:C,A10,'muddati otgan'!J:J,"Tekshirish") -> 0 | BN10: =+COUNTIFS('muddati otgan'!C:C,A10,'muddati otgan'!J:J,"Hujjatlarni tekshirish") -> 0 | BO10: =+COUNTIFS('muddati otgan'!C:C,A10,'muddati otgan'!J:J,"Tasdiqlash") -> 0 | BP10: =+COUNTIFS('muddati otgan'!C:C,A10,'muddati otgan'!J:J,"tekshirish/tasdiqlash") -> 0 | BQ10: =+COUNTIFS('muddati otgan'!C:C,A10,'muddati otgan'!J:J,"Ma'lumotlarni tasdiqlash") -> 0 | BR10: =BS10+BU10+BV10+BW10+BX10+BY10-BT10 -> 0 | BS10: =+COUNTIFS('muddati otgan'!C:C,A10,'muddati otgan'!J:J,"Ro'yxatdan o'tkazish ma'lumotlarini tekshirish") -> 0 | BT10: =+COUNTIFS('muddati otgan'!C:C,A10,'muddati otgan'!J:J,"Kamchiliklar bo'yicha habarnoma yuborish va 3 kunga to'xtatish") -> 0 | BU10: =+COUNTIFS('muddati otgan'!C:C,A10,'muddati otgan'!J:J,"Hisobga olish") -> 0 | BV10: =+COUNTIFS('muddati otgan'!C:C,A10,'muddati otgan'!J:J,"Yer uchastkasiga huquq yaratish") -> 0 | BW10: =+COUNTIFS('muddati otgan'!C:C,A10,'muddati otgan'!J:J,"Bino-inshootga huquq yaratish") -> 0 | BX10: =+COUNTIFS('muddati otgan'!C:C,A10,'muddati otgan'!J:J,"Cheklov yaratish") -> 0 | BY10: =+COUNTIFS('muddati otgan'!C:C,A10,'muddati otgan'!J:J,"Taqiq yaratish") -> 0 | BZ10: =CA10 -> 0 | CA10: =+COUNTIFS('muddati otgan'!C:C,A10,'muddati otgan'!J:J,"Soliq maydonini tekshirish") -> 0 | CB10: =CC10 -> 0 | CC10: =+COUNTIFS('muddati otgan'!C:C,A10,'muddati otgan'!J:J,"Kadastr yig'majildini shakllantirish") -> 0 | CD10: =CE10+CF10+CG10+CI10+CJ10+CH10 -> 0 | CE10: =+COUNTIFS('muddati otgan'!C:C,A10,'muddati otgan'!J:J,"Kadastr passportini shakllantirish") -> 0 | CF10: =+COUNTIFS('muddati otgan'!C:C,A10,'muddati otgan'!J:J,"Yig'ma jildni tasdiqlash") -> 0 | CG10: =+COUNTIFS('muddati otgan'!C:C,A10,'muddati otgan'!J:J,"To'lov yoki bepul tasdiqlash") -> 0 | CH10: =+COUNTIFS('muddati otgan'!C:C,A10,'muddati otgan'!J:J,"Bog'liq arizani kutish") -> 0 | CI10: =+COUNTIFS('muddati otgan'!C:C,A10,'muddati otgan'!J:J,"To'lovga chiqarish") -> 0 | CJ10: =+COUNTIFS('muddati otgan'!C:C,A10,'muddati otgan'!J:J,"Hisobga qo'yish") -> 0 | CK10: =+COUNTIFS('muddati otgan'!C:C,A10,'muddati otgan'!J:J,"To'lov kutilmoqda") -> 1 | CL10: =CM10+CN10+CO10+CP10+CQ10+CR10+CS10+CT10 -> 0 | CM10: =+COUNTIFS('muddati otgan'!C:C,A10,'muddati otgan'!AA:AA,"Arizani qabul qilish2") -> 0 | CN10: =+COUNTIFS('muddati otgan'!C:C,A10,'muddati otgan'!J:J,"Huquqlarni tekshirish") -> 0 | CO10: =+COUNTIFS('muddati otgan'!C:C,A10,'muddati otgan'!J:J,"Ko'chmas mulkni ro'yhatdan o'tkazishga qabul qilish") -> 0 | CP10: =+COUNTIFS('muddati otgan'!C:C,A10,'muddati otgan'!J:J,"Ro'yxatdan o'tkazish") -> 0 | CQ10: =+COUNTIFS('muddati otgan'!C:C,A10,'muddati otgan'!J:J,"Kadastr pasporti va ko'chirmani yuborish") -> 0 | CR10: =+COUNTIFS('muddati otgan'!C:C,A10,'muddati otgan'!AA:AA,"Rad qilish2") -> 0 | CS10: =+COUNTIFS('muddati otgan'!C:C,A10,'muddati otgan'!J:J,"Ko'chirmani yuborish") -> 0 | CT10: =+COUNTIFS('muddati otgan'!C:C,A10,'muddati otgan'!J:J,"Ma‘lumotlarni tekshirish") -> 0 | CU10: =CV10 -> 0 | CV10: =+COUNTIFS('muddati otgan'!C:C,A10,'muddati otgan'!J:J,"Kadastr yig'majildini chop etish va arxiv ishiga tikish") -> 0 | CW10: =CX10+CY10 -> 0 | CX10: =+COUNTIFS('muddati otgan'!C:C,A10,'muddati otgan'!J:J,"Kadastr yig‘majildini qabul qilish, arizani yakunlash") -> 0 | CY10: =+COUNTIFS('muddati otgan'!C:C,A10,'muddati otgan'!J:J,"Next Cloudga yuklash") -> 0 | CZ10: =+COUNTIFS('muddati otgan'!C:C,A10,'muddati otgan'!J:J,"Kelishish kutilmoqda") -> 0 | DA10: =+COUNTIFS('muddati otgan'!C:C,A10,'muddati otgan'!J:J,"Yakunlandi") -> 2 | DB10: =+COUNTIFS('muddati otgan'!C:C,A10,'muddati otgan'!J:J,"Rad etildi") -> 0 | DC10: =CK10+CZ10+DA10+DB10-D10 -> 0 | DD10: =COUNTIFS('jami 1-20 kunlik arizalar'!C:C,A:A,'jami 1-20 kunlik arizalar'!S:S,"1") -> 0 | DE10: =COUNTIFS('jami 1-20 kunlik arizalar'!C:C,A:A,'jami 1-20 kunlik arizalar'!S:S,"2") -> 0 | DF10: =COUNTIFS('jami 1-20 kunlik arizalar'!C:C,A:A,'jami 1-20 kunlik arizalar'!S:S,"3") -> 0 | DG10: =COUNTIFS('jami 1-20 kunlik arizalar'!C:C,A:A,'jami 1-20 kunlik arizalar'!S:S,"4") -> 1 | DH10: =COUNTIFS('jami 1-20 kunlik arizalar'!C:C,A:A,'jami 1-20 kunlik arizalar'!S:S,"5") -> 1 | DI10: =SUM(COUNTIFS('jami 1-20 kunlik arizalar'!C:C,A:A, 'jami 1-20 kunlik arizalar'!S:S, {6,7,8,9,10})) -> 3 | DJ10: =SUM(COUNTIFS('jami 1-20 kunlik arizalar'!C:C,A:A, 'jami 1-20 kunlik arizalar'!S:S,">10")) -> 10
